################################################################################
Concuerror started with options:
  [{after_timeout,infinity},
   {assume_racing,false},
   {delay_bound,infinity},
   {depth_bound,5000},
   {entry_point,{trigger_the_after,trigger_the_after,[]}},
   {files,["/home/stavros/git/Concuerror/tests/suites/basic_tests/src/trigger_the_after.erl"]},
   {ignore_error,[]},
   {ignore_first_crash,true},
   {instant_delivery,false},
   {non_racing_system,[]},
   {optimal,true},
   {print_depth,20},
   {quiet,true},
   {scheduling,round_robin},
   {show_races,false},
   {strict_scheduling,false},
   {symbolic_names,true},
   {timeout,infinity},
   {treat_as_normal,[]}]
################################################################################
Erroneous interleaving 1:
* At step 4 process P exited abnormally
    Reason:
      {error,
          [{trigger_the_after,trigger_the_after,0,
               [{file,
                    "/home/stavros/git/Concuerror/tests/suites/basic_tests/src/trigger_the_after.erl"},
                {line,12}]}]}
    Stacktrace:
      [{trigger_the_after,trigger_the_after,0,
                          [{file,"/home/stavros/git/Concuerror/tests/suites/basic_tests/src/trigger_the_after.erl"},
                           {line,12}]}]
* At step 13 process P.1 exited abnormally
    Reason:
      {{nocatch,both},
       [{trigger_the_after,receive_two,0,
                           [{file,"/home/stavros/git/Concuerror/tests/suites/basic_tests/src/trigger_the_after.erl"},
                            {line,18}]}]}
    Stacktrace:
      [{trigger_the_after,receive_two,0,
                          [{file,"/home/stavros/git/Concuerror/tests/suites/basic_tests/src/trigger_the_after.erl"},
                           {line,18}]}]
--------------------------------------------------------------------------------
Interleaving info:
   1: P: P.1 = erlang:spawn(erlang, apply, [#Fun<trigger_the_after.0.103202625>,[]])
    in erlang.erl line 2329
   2: P: P.2 = erlang:spawn(erlang, apply, [#Fun<trigger_the_after.3.103202625>,[]])
    in erlang.erl line 2329
   3: P: P.3 = erlang:spawn(erlang, apply, [#Fun<trigger_the_after.3.103202625>,[]])
    in erlang.erl line 2329
   4: P: exits abnormally ({error,[{trigger_the_after,trigger_the_after,0,[{file,[47,104,111,109,101,47,115,116,97|...]},{line,12}]}]})
   5: P.2: two = P.1 ! two
    in trigger_the_after.erl line 25
   6: P.2: exits normally
   7: Message (two) from P.2 reaches P.1
   8: P.3: one = P.1 ! one
    in trigger_the_after.erl line 25
   9: P.3: exits normally
  10: Message (one) from P.3 reaches P.1
  11: P.1: receives message (one)
    in trigger_the_after.erl line 15
  12: P.1: receives message (two)
    in trigger_the_after.erl line 17
  13: P.1: exits abnormally ({{nocatch,both},[{trigger_the_after,receive_two,0,[{file,[47,104,111,109,101,47,115,116,97|...]},{line,18}]}]})
################################################################################
Erroneous interleaving 2:
* At step 4 process P exited abnormally
    Reason:
      {error,
          [{trigger_the_after,trigger_the_after,0,
               [{file,
                    "/home/stavros/git/Concuerror/tests/suites/basic_tests/src/trigger_the_after.erl"},
                {line,12}]}]}
    Stacktrace:
      [{trigger_the_after,trigger_the_after,0,
                          [{file,"/home/stavros/git/Concuerror/tests/suites/basic_tests/src/trigger_the_after.erl"},
                           {line,12}]}]
* At step 12 process P.1 exited abnormally
    Reason:
      {{nocatch,one},
       [{trigger_the_after,receive_two,0,
                           [{file,"/home/stavros/git/Concuerror/tests/suites/basic_tests/src/trigger_the_after.erl"},
                            {line,20}]}]}
    Stacktrace:
      [{trigger_the_after,receive_two,0,
                          [{file,"/home/stavros/git/Concuerror/tests/suites/basic_tests/src/trigger_the_after.erl"},
                           {line,20}]}]
--------------------------------------------------------------------------------
Interleaving info:
   1: P: P.1 = erlang:spawn(erlang, apply, [#Fun<trigger_the_after.0.103202625>,[]])
    in erlang.erl line 2329
   2: P: P.2 = erlang:spawn(erlang, apply, [#Fun<trigger_the_after.3.103202625>,[]])
    in erlang.erl line 2329
   3: P: P.3 = erlang:spawn(erlang, apply, [#Fun<trigger_the_after.3.103202625>,[]])
    in erlang.erl line 2329
   4: P: exits abnormally ({error,[{trigger_the_after,trigger_the_after,0,[{file,[47,104,111,109,101,47,115,116,97|...]},{line,12}]}]})
   5: P.2: two = P.1 ! two
    in trigger_the_after.erl line 25
   6: P.2: exits normally
   7: P.3: one = P.1 ! one
    in trigger_the_after.erl line 25
   8: P.3: exits normally
   9: Message (one) from P.3 reaches P.1
  10: P.1: receives message (one)
    in trigger_the_after.erl line 15
  11: P.1: receive timeout expired after 100 ms
    in trigger_the_after.erl line 17
  12: P.1: exits abnormally ({{nocatch,one},[{trigger_the_after,receive_two,0,[{file,[47,104,111,109,101,47,115,116,97|...]},{line,20}]}]})
  13: Message (two) from P.2 reaches P.1
################################################################################
Erroneous interleaving 3:
* At step 4 process P exited abnormally
    Reason:
      {error,
          [{trigger_the_after,trigger_the_after,0,
               [{file,
                    "/home/stavros/git/Concuerror/tests/suites/basic_tests/src/trigger_the_after.erl"},
                {line,12}]}]}
    Stacktrace:
      [{trigger_the_after,trigger_the_after,0,
                          [{file,"/home/stavros/git/Concuerror/tests/suites/basic_tests/src/trigger_the_after.erl"},
                           {line,12}]}]
* At step 13 process P.1 exited abnormally
    Reason:
      {{nocatch,both},
       [{trigger_the_after,receive_two,0,
                           [{file,"/home/stavros/git/Concuerror/tests/suites/basic_tests/src/trigger_the_after.erl"},
                            {line,18}]}]}
    Stacktrace:
      [{trigger_the_after,receive_two,0,
                          [{file,"/home/stavros/git/Concuerror/tests/suites/basic_tests/src/trigger_the_after.erl"},
                           {line,18}]}]
--------------------------------------------------------------------------------
Interleaving info:
   1: P: P.1 = erlang:spawn(erlang, apply, [#Fun<trigger_the_after.0.103202625>,[]])
    in erlang.erl line 2329
   2: P: P.2 = erlang:spawn(erlang, apply, [#Fun<trigger_the_after.3.103202625>,[]])
    in erlang.erl line 2329
   3: P: P.3 = erlang:spawn(erlang, apply, [#Fun<trigger_the_after.3.103202625>,[]])
    in erlang.erl line 2329
   4: P: exits abnormally ({error,[{trigger_the_after,trigger_the_after,0,[{file,[47,104,111,109,101,47,115,116,97|...]},{line,12}]}]})
   5: P.2: two = P.1 ! two
    in trigger_the_after.erl line 25
   6: P.2: exits normally
   7: P.3: one = P.1 ! one
    in trigger_the_after.erl line 25
   8: P.3: exits normally
   9: Message (one) from P.3 reaches P.1
  10: P.1: receives message (one)
    in trigger_the_after.erl line 15
  11: Message (two) from P.2 reaches P.1
  12: P.1: receives message (two)
    in trigger_the_after.erl line 17
  13: P.1: exits abnormally ({{nocatch,both},[{trigger_the_after,receive_two,0,[{file,[47,104,111,109,101,47,115,116,97|...]},{line,18}]}]})
################################################################################
Concuerror Info:
--------------------------------------------------------------------------------
Instrumented: trigger_the_after
Instrumented: io_lib
Instrumented: gen_server
Hijacked application_controller
Instrumented: erlang
################################################################################
Done! (Exit status: completed)
  Summary: 3 errors, 3/3 interleavings explored
